Traceback (most recent call last):
  File "/opt/hostedtoolcache/Python/3.10.14/x64/lib/python3.10/site-packages/jupyter_cache/executors/utils.py", line 58, in single_nb_execution
    executenb(
  File "/opt/hostedtoolcache/Python/3.10.14/x64/lib/python3.10/site-packages/nbclient/client.py", line 1314, in execute
    return NotebookClient(nb=nb, resources=resources, km=km, **kwargs).execute()
  File "/opt/hostedtoolcache/Python/3.10.14/x64/lib/python3.10/site-packages/jupyter_core/utils/__init__.py", line 165, in wrapped
    return loop.run_until_complete(inner)
  File "/opt/hostedtoolcache/Python/3.10.14/x64/lib/python3.10/asyncio/base_events.py", line 649, in run_until_complete
    return future.result()
  File "/opt/hostedtoolcache/Python/3.10.14/x64/lib/python3.10/site-packages/nbclient/client.py", line 709, in async_execute
    await self.async_execute_cell(
  File "/opt/hostedtoolcache/Python/3.10.14/x64/lib/python3.10/site-packages/nbclient/client.py", line 1062, in async_execute_cell
    await self._check_raise_for_error(cell, cell_index, exec_reply)
  File "/opt/hostedtoolcache/Python/3.10.14/x64/lib/python3.10/site-packages/nbclient/client.py", line 918, in _check_raise_for_error
    raise CellExecutionError.from_cell_and_msg(cell, exec_reply_content)
nbclient.exceptions.CellExecutionError: An error occurred while executing the following cell:
------------------
from sklearn.tree import DecisionTreeClassifier

decision_tree_classifier = DecisionTreeClassifier(max_depth=5)
run_classifier(decision_tree_classifier, data, labels)
run_classifier(decision_tree_classifier, data2, labels2)
------------------


[0;31m---------------------------------------------------------------------------[0m
[0;31mNameError[0m                                 Traceback (most recent call last)
Cell [0;32mIn[1], line 4[0m
[1;32m      1[0m [38;5;28;01mfrom[39;00m [38;5;21;01msklearn[39;00m[38;5;21;01m.[39;00m[38;5;21;01mtree[39;00m [38;5;28;01mimport[39;00m DecisionTreeClassifier
[1;32m      3[0m decision_tree_classifier [38;5;241m=[39m DecisionTreeClassifier(max_depth[38;5;241m=[39m[38;5;241m5[39m)
[0;32m----> 4[0m [43mrun_classifier[49m(decision_tree_classifier, data, labels)
[1;32m      5[0m run_classifier(decision_tree_classifier, data2, labels2)

[0;31mNameError[0m: name 'run_classifier' is not defined

